2019-11-24 15:55:22,078 ERROR: Exception on /user/shadi [GET] [in c:\program files (x86)\python\lib\site-packages\flask\app.py:1780]
Traceback (most recent call last):
  File "C:\Users\shadi\AppData\Roaming\Python\Python37\site-packages\sqlalchemy\engine\base.py", line 1246, in _execute_context
    cursor, statement, parameters, context
  File "C:\Users\shadi\AppData\Roaming\Python\Python37\site-packages\sqlalchemy\engine\default.py", line 581, in do_execute
    cursor.execute(statement, parameters)
sqlite3.OperationalError: no such table: followers

The above exception was the direct cause of the following exception:

Traceback (most recent call last):
  File "c:\program files (x86)\python\lib\site-packages\flask\app.py", line 2311, in wsgi_app
    response = self.full_dispatch_request()
  File "c:\program files (x86)\python\lib\site-packages\flask\app.py", line 1834, in full_dispatch_request
    rv = self.handle_user_exception(e)
  File "c:\program files (x86)\python\lib\site-packages\flask\app.py", line 1737, in handle_user_exception
    reraise(exc_type, exc_value, tb)
  File "c:\program files (x86)\python\lib\site-packages\flask\_compat.py", line 36, in reraise
    raise value
  File "c:\program files (x86)\python\lib\site-packages\flask\app.py", line 1832, in full_dispatch_request
    rv = self.dispatch_request()
  File "c:\program files (x86)\python\lib\site-packages\flask\app.py", line 1818, in dispatch_request
    return self.view_functions[rule.endpoint](**req.view_args)
  File "c:\program files (x86)\python\lib\site-packages\flask_login\utils.py", line 261, in decorated_view
    return func(*args, **kwargs)
  File "C:\Users\shadi\Desktop\mjamilblog\app\routes.py", line 82, in user
    next_url=next_url, prev_url=prev_url)
  File "c:\program files (x86)\python\lib\site-packages\flask\templating.py", line 135, in render_template
    context, ctx.app)
  File "c:\program files (x86)\python\lib\site-packages\flask\templating.py", line 117, in _render
    rv = template.render(context)
  File "c:\program files (x86)\python\lib\site-packages\jinja2\asyncsupport.py", line 76, in render
    return original_render(self, *args, **kwargs)
  File "c:\program files (x86)\python\lib\site-packages\jinja2\environment.py", line 1008, in render
    return self.environment.handle_exception(exc_info, True)
  File "c:\program files (x86)\python\lib\site-packages\jinja2\environment.py", line 780, in handle_exception
    reraise(exc_type, exc_value, tb)
  File "c:\program files (x86)\python\lib\site-packages\jinja2\_compat.py", line 37, in reraise
    raise value.with_traceback(tb)
  File "C:\Users\shadi\Desktop\mjamilblog\app\templates\user.html", line 1, in top-level template code
    {% extends "base.html" %}
  File "C:\Users\shadi\Desktop\mjamilblog\app\templates\base.html", line 1, in top-level template code
    {% extends 'bootstrap/base.html' %}
  File "c:\program files (x86)\python\lib\site-packages\flask_bootstrap\templates\bootstrap\base.html", line 1, in top-level template code
    {% block doc -%}
  File "c:\program files (x86)\python\lib\site-packages\flask_bootstrap\templates\bootstrap\base.html", line 4, in block "doc"
    {%- block html %}
  File "c:\program files (x86)\python\lib\site-packages\flask_bootstrap\templates\bootstrap\base.html", line 20, in block "html"
    {% block body -%}
  File "c:\program files (x86)\python\lib\site-packages\flask_bootstrap\templates\bootstrap\base.html", line 23, in block "body"
    {% block content -%}
  File "C:\Users\shadi\Desktop\mjamilblog\app\templates\user.html", line 11, in block "content"
    <p>{{ user.followers.count() }} followers, {{ user.followed.count() }} following.</p>
  File "C:\Users\shadi\AppData\Roaming\Python\Python37\site-packages\sqlalchemy\orm\dynamic.py", line 335, in count
    return self._clone(sess).count()
  File "C:\Users\shadi\AppData\Roaming\Python\Python37\site-packages\sqlalchemy\orm\query.py", line 3630, in count
    return self.from_self(col).scalar()
  File "C:\Users\shadi\AppData\Roaming\Python\Python37\site-packages\sqlalchemy\orm\query.py", line 3355, in scalar
    ret = self.one()
  File "C:\Users\shadi\AppData\Roaming\Python\Python37\site-packages\sqlalchemy\orm\query.py", line 3325, in one
    ret = self.one_or_none()
  File "C:\Users\shadi\AppData\Roaming\Python\Python37\site-packages\sqlalchemy\orm\query.py", line 3294, in one_or_none
    ret = list(self)
  File "C:\Users\shadi\AppData\Roaming\Python\Python37\site-packages\sqlalchemy\orm\query.py", line 3367, in __iter__
    return self._execute_and_instances(context)
  File "C:\Users\shadi\AppData\Roaming\Python\Python37\site-packages\sqlalchemy\orm\query.py", line 3392, in _execute_and_instances
    result = conn.execute(querycontext.statement, self._params)
  File "C:\Users\shadi\AppData\Roaming\Python\Python37\site-packages\sqlalchemy\engine\base.py", line 982, in execute
    return meth(self, multiparams, params)
  File "C:\Users\shadi\AppData\Roaming\Python\Python37\site-packages\sqlalchemy\sql\elements.py", line 287, in _execute_on_connection
    return connection._execute_clauseelement(self, multiparams, params)
  File "C:\Users\shadi\AppData\Roaming\Python\Python37\site-packages\sqlalchemy\engine\base.py", line 1101, in _execute_clauseelement
    distilled_params,
  File "C:\Users\shadi\AppData\Roaming\Python\Python37\site-packages\sqlalchemy\engine\base.py", line 1250, in _execute_context
    e, statement, parameters, cursor, context
  File "C:\Users\shadi\AppData\Roaming\Python\Python37\site-packages\sqlalchemy\engine\base.py", line 1476, in _handle_dbapi_exception
    util.raise_from_cause(sqlalchemy_exception, exc_info)
  File "C:\Users\shadi\AppData\Roaming\Python\Python37\site-packages\sqlalchemy\util\compat.py", line 398, in raise_from_cause
    reraise(type(exception), exception, tb=exc_tb, cause=cause)
  File "C:\Users\shadi\AppData\Roaming\Python\Python37\site-packages\sqlalchemy\util\compat.py", line 152, in reraise
    raise value.with_traceback(tb)
  File "C:\Users\shadi\AppData\Roaming\Python\Python37\site-packages\sqlalchemy\engine\base.py", line 1246, in _execute_context
    cursor, statement, parameters, context
  File "C:\Users\shadi\AppData\Roaming\Python\Python37\site-packages\sqlalchemy\engine\default.py", line 581, in do_execute
    cursor.execute(statement, parameters)
sqlalchemy.exc.OperationalError: (sqlite3.OperationalError) no such table: followers
[SQL: SELECT count(*) AS count_1 
FROM (SELECT user.id AS user_id, user.username AS user_username, user.email AS user_email, user.password_hash AS user_password_hash, user.about_me AS user_about_me, user.last_seen AS user_last_seen 
FROM user, followers 
WHERE followers.followed_id = ? AND followers.follower_id = user.id) AS anon_1]
[parameters: (1,)]
(Background on this error at: http://sqlalche.me/e/e3q8)
